Sources:
https://blog.csdn.net/sinat_34850075/article/details/52434526
https://github.com/scottransom/presto/blob/master/INSTALL
https://docs.google.com/document/d/1v8Dm4f-SOeDQX5Yli6syek1pxtqgpw81b1cxqoqv2aU
http://zhaozhen.me/2017/10/16/ubuntu-software-presto.html



What I've run on my Ubuntu 18.04 64 bit to install PRESTO, for use in _Python_:

	sudo apt-get update

	cd ~
	mkdir PULSAR_SOFTWARES
I know this is a spelling mistake I will never get rid of... RIP me.

	sudo apt-get install git libfftw3-bin libfftw3-dbg libfftw3-dev libfftw3-doc libfftw3-double3 libfftw3-long3 libfftw3-quad3 libfftw3-single3 pgplot5 csh automake gfortran libglib2.0-dev libccfits-dev libcfitsio5 libcfitsio-dev libx11-dev libpng-dev 

	cd PULSAR_SOFTWARES/


	git clone http://git.code.sf.net/p/tempo/tempo

	cd tempo
	./prepare
	./configure
	make && sudo make install
	cp tempo.cfg src/
	cp tempo.hlp src/
	cd ..

	git clone http://github.com/scottransom/presto.git





	sudo gedit /etc/environment

added to the end of my PATH:
	:/home/emma/PULSAR_SOFTWARES/presto/bin"

then added:
	TEMPO="/home/emma/PULSAR_SOFTWARES/tempo/src"

	PRESTO="/home/emma/PULSAR_SOFTWARES/presto"

	PGPLOT_DIR="/usr/lib/pgplot5"

	FFTW_PATH="/usr"

	LD_LIBRARY_PATH="/home/emma/PULSAR_SOFTWARES/presto/lib"







	git clone https://github.com/scottransom/pyslalib.git
	cd pyslalib
	python setup.py install


	cd /home/emma/PULSAR_SOFTWARES/presto/src


	make makewisdom
	make prep
	make
	make clean


	cd $PRESTO ; pip install .


Then tried to run /home/emma/PULSAR_SOFTWARES/presto/tests/test_presto_python.py
Got error "libpresto.so: cannot open shared object file: No such file or directory" so I did this, according to  https://summerpulsar.wordpress.com/2015/01/12/more-presto-installation/
	cd lib
	sudo cp libpresto.so /usr/lib

Then my kernel was crashing completely, for the following tests (errors next to them):
- Reading / Writing infiles (which I need) [no errors]
- Allocation and freeing of memory [double free or corruption (out)]
- Spectral power and spectral phase [double free or corruption (out)]
- Tempo get baryv [At line 284 of file arrtim.f
Fortran runtime error: Bad value during floating point read

Error termination. Backtrace:
#0 0x7f8620a342da in ???
#1 0x7f8620a34ec5 in ???
#2 0x7f8620a3568d in ???
#3 0x7f8620ba9afd in ???
#4 0x7f8620bace38 in ???
#5 0x7f8620bae4bc in ???
#6 0x55bc1de1214b in arrtim_
at /home/emma/PULSAR_SOFTWARES/tempo/src/arrtim.f:284
#7 0x55bc1de517b9 in tempo
at /home/emma/PULSAR_SOFTWARES/tempo/src/tempo.f:442
#8 0x55bc1de0dcfe in main
at /home/emma/PULSAR_SOFTWARES/tempo/src/tempo.f:511

Error in chkfopen(): No such file or directory]

Those are all Fortran errors. 
Rest was working fine. 
Seems to happen to someone else, could be an anaconda problem: https://github.com/scottransom/presto/issues/73


Things tried:
tried installing nvidia-cuda-dev and libcuda-340
tried adding a pyslalib so file to my LIB path
ran pyslalib test which came out OK 'python test/test_slalib.py' in PULSAR_SOFTWARES/pyslalib


Next up:
try folding, ignoring the python_test
if doesnt work, install from https://kernsuite.info/


